Workbook

Sheet 2026
A1: Planejamento 2026 - We Make
B3: Contratos (2026) | C3: Mês | D3: Ano
A4: 1 | B4: Colégio Graciosa (ano 3/3) | C4: 10500 | D4: =C4*12 -> 126000
A5: 2 | B5: Colégio Presbiteriano de Sete Lagoas (rescisão) | C5: 1200 | D5: =C5*12 -> 14400
A6: 3 | B6: Colégio Cristão Amar (ano 2/4) | C6: 4500 | D6: =C6*12 -> 54000
A7: 4 | B7: Colégio Journey (ano 2/5) | C7: 4945 | D7: =C7*12 -> 59340
A8: 5 | B8: Executivo Colégio e Curso (gratuito) | C8: 0 | D8: =C8*12 -> 0
A9: 6 | B9: Escola Cristã do Reino (1/4) | C9: 480 | D9: =C9*12 -> 5760
A10: 7 | B10: Escola Aprender e Viver (1/4) | C10: 0 | D10: =C10*12 -> 0
A11: 8 | B11: Educar Londrina (1/4) | C11: 5274.91 | D11: =C11*12 -> 63298.92
A12: 9 | B12: CESE (1/4) | C12: 3150 | D12: =C12*12 -> 37800
A13: 10 | B13: CEA (1/4) | C13: 450 | D13: =C13*12 -> 5400
A14: 11 | B14: Sagrados corações (1/4) | C14: 900 | D14: =C14*12 -> 10800
A15: 12 | B15: ACR Classical Christian School | C15: 840 | D15: =C15*12 -> 10080

Sheet 2027
A1: Planejamento 2027 - We Make
B3: Contratos (2026) | C3: jan | D3: fev | E3: mar | F3: abr | G3: mai | H3: jun | I3: jul | J3: ago | K3: set | L3: out | M3: nov | N3: dez | O3: Ano | P3: Observações
A4: 1 | B4: Colégio Graciosa (ano 1/4) | C4: 8125.04 | D4: 8125.04 | E4: 8125.04 | F4: 8125.04 | G4: 8125.04 | H4: 8125.04 | I4: 8125.04 | J4: 8125.04 | K4: 8125.04 | L4: 8125.04 | M4: 8125.04 | N4: 8125.04 | O4: =N4*12 -> 97500.48 | P4: Livro incluso
A5: 2 | B5: Colégio Presbiteriano de Sete Lagoas (rescisão) | C5: 1200 | D5: 1200 | E5: 1200 | F5: 1200 | O5: =SUM(C5:F5) -> 4800 | P5: Rescisão
A6: 3 | B6: Colégio Cristão Amar (ano 3/4) | C6: 6900 | D6: 6900 | E6: 6900 | F6: 6900 | G6: 6900 | H6: 6900 | I6: 6900 | J6: 6900 | K6: 6900 | L6: 6900 | M6: 6900 | N6: 6900 | O6: =N6*12 -> 82800 | P6: Pagam hoje por aluno 345,00. Podemos aumentar 380,00 com o livro.
A7: 4 | B7: Colégio Journey (ano 3/5) | C7: 8208 | D7: 8208 | E7: 8208 | F7: 8208 | G7: 8208 | H7: 8208 | I7: 8208 | J7: 8208 | K7: 8208 | L7: 8208 | M7: 8208 | N7: 8208 | O7: =N7*12 -> 98496 | P7: Pagam hoje por aluno 288,00. Podemos aumentar 360,00 com o livro.
A8: 5 | B8: Executivo Colégio e Curso (gratuito) | C8: 0 | D8: 0 | E8: 0 | F8: 0 | G8: 0 | H8: 0 | I8: 0 | J8: 0 | K8: 0 | L8: 0 | M8: 0 | N8: 0 | O8: =N8*12 -> 0
A9: 6 | B9: Escola Cristã do Reino (2/4) | C9: 498 | D9: 498 | E9: 498 | F9: 498 | G9: 498 | H9: 498 | I9: 498 | J9: 498 | K9: 498 | L9: 498 | M9: 498 | N9: 498 | O9: =N9*12 -> 5976 | P9: Pagam hoje por aluno 249,00. Podemos aumentar 310,00 com o livro.
A10: 7 | B10: Escola Aprender e Viver (2/4) | C10: 5416.66 | D10: 5416.66 | E10: 5416.66 | F10: 5416.66 | G10: 5416.66 | H10: 5416.66 | I10: 5416.66 | J10: 5416.66 | K10: 5416.66 | L10: 5416.66 | M10: 5416.66 | N10: 5416.66 | O10: =N10*12 -> 64999.92 | P10: Livro incluso
A11: 8 | B11: Educar Londrina (2/4) | C11: 5579.1813 | D11: 5579.1813 | E11: 5579.1813 | F11: 5579.1813 | G11: 5579.1813 | H11: 5579.1813 | I11: 5579.1813 | J11: 5579.1813 | K11: 5579.1813 | L11: 5579.1813 | M11: 5579.1813 | N11: 5579.1813 | O11: =N11*12 -> 66950.176 | P11: Pagam hoje por aluno 198,00. Podemos aumentar 350,00 com o livro.
A12: 9 | B12: CESE (2/4) | C12: 3307.815 | D12: 3307.815 | E12: 3307.815 | F12: 3307.815 | G12: 3307.815 | H12: 3307.815 | I12: 3307.815 | J12: 3307.815 | K12: 3307.815 | L12: 3307.815 | M12: 3307.815 | N12: 3307.815 | O12: =N12*12 -> 39693.78 | P12: Pagam hoje por aluno 180,00. Podemos aumentar 300,00 com o livro.
A13: 10 | B13: CEA (2/4) | C13: 472.545 | D13: 472.545 | E13: 472.545 | F13: 472.545 | G13: 472.545 | H13: 472.545 | I13: 472.545 | J13: 472.545 | K13: 472.545 | L13: 472.545 | M13: 472.545 | N13: 472.545 | O13: =N13*12 -> 5670.54 | P13: Pagam hoje por aluno 180,00. Podemos aumentar 280,00 com o livro.
A14: 11 | B14: Sagrados corações (2/4) | C14: 1050 | D14: 1050 | E14: 1050 | F14: 1050 | G14: 1050 | H14: 1050 | I14: 1050 | J14: 1050 | K14: 1050 | L14: 1050 | M14: 1050 | N14: 1050 | O14: =N14*12 -> 12600 | P14: Pagam hoje por aluno 210,00. Podemos aumentar 350 com o livro.
A15: 12 | B15: ACR Classical Christian School (2/4) | C15: 976.5 | D15: 976.5 | E15: 976.5 | F15: 976.5 | G15: 976.5 | H15: 976.5 | I15: 976.5 | J15: 976.5 | K15: 976.5 | L15: 976.5 | M15: 976.5 | N15: 976.5 | O15: =N15*12 -> 11718 | P15: Pagam hoje por aluno 279,00. Podemos aumentar 350 com o livro.
A16: 13 | B16: Escola Cristã Paz (1/4) | C16: 3762 | D16: 3762 | E16: 3762 | F16: 3762 | G16: 3762 | H16: 3762 | I16: 3762 | J16: 3762 | K16: 3762 | L16: 3762 | M16: 3762 | N16: 3762 | O16: =N16*12 -> 45144 | P16: Escola nova. Pagam hoje por aluno 250,80. Podemos aumentar 350,00 com o livro.
A17: 14 | B17: Colégio da Comunidade - Curuçá (1/4) | C17: 20257.2 | D17: 20257.2 | E17: 20257.2 | F17: 20257.2 | G17: 20257.2 | O17: =SUM(C17:N17) -> 101286 | P17: Livro incluso
A18: 15 | B18: Colégio da Comunidade - Carrão (1/4) | C18: 16646.4 | D18: 16646.4 | E18: 16646.4 | F18: 16646.4 | G18: 16646.4 | O18: =SUM(C18:N18) -> 83232 | P18: Livro incluso
A19: 16 | B19: Escola Estímulos (1/4) | C19: 0 | D19: 0 | E19: 0 | F19: 0 | G19: 0 | O19: =SUM(C19:N19) -> 0 | P19: Sorteio
A20: 17 | B20: Colégio Cristão Reverendo Olavo Nunes (1/4) | C20: 5175 | D20: 5175 | E20: 5175 | F20: 5175 | G20: 5175 | O20: =SUM(C20:N20) -> 25875 | P20: Livro incluso
A21: 18 | B21: Colégio Cristão Zoe (1/4) | C21: 3900 | D21: 3900 | E21: 3900 | F21: 3900 | G21: 3900 | O21: =SUM(C21:N21) -> 19500 | P21: Livro incluso
A22: 19 | B22: Colégio Lighthouse F1 (1/4) | C22: 4548.6 | D22: 4548.6 | E22: 4548.6 | F22: 4548.6 | G22: 4548.6 | O22: =SUM(C22:N22) -> 22743 | P22: Livro incluso
A23: 20 | B23: Colégio Lighthouse F2 (1/4) | C23: 4708.2 | D23: 4708.2 | E23: 4708.2 | F23: 4708.2 | G23: 4708.2 | O23: =SUM(C23:N23) -> 23541 | P23: Livro incluso
A24: 21 | B24: Bee Christian School (1/5) | C24: 9100 | D24: 9100 | E24: 9100 | F24: 9100 | G24: 9100 | O24: =SUM(C24:N24) -> 45500 | P24: Livro incluso
A25: 22 | B25: For Life (1/4) | C25: 10260 | D25: 10260 | E25: 10260 | F25: 10260 | G25: 10260 | O25: =SUM(C25:N25) -> 51300 | P25: Livro incluso
A26: 23 | B26: Escola Supremo | C26: 8527.2 | D26: 8527.2 | E26: 8527.2 | F26: 8527.2 | G26: 8527.2 | O26: =SUM(C26:N26) -> 42636 | P26: Livro incluso
B27: Total | C27: =SUM(C4:C26) -> 128618.34 | D27: =SUM(D4:D26) -> 128618.34 | E27: =SUM(E4:E26) -> 128618.34 | F27: =SUM(F4:F26) -> 128618.34 | G27: =SUM(G4:G26) -> 127418.34 | H27: =SUM(H4:H26) -> 44295.741 | I27: =SUM(I4:I26) -> 44295.741 | J27: =SUM(J4:J26) -> 44295.741 | ... O27: =SUM(O4:O26) -> 951961.9
B30: Gasto Corrente | C30: jan | D30: fev | E30: mar | F30: abr | G30: mai | H30: jun | I30: jul | J30: ago | K30: set | L30: out | M30: nov | N30: dez | O30: total
B31: DESPESA TOTAL | C31: =SUM(C32,C46,C124,C132,C137,C149,C159,C166,C171,C177,C196,C202) -> 61619.429 | D31: =SUM(D32,D46,D124,D132,D137,D149,D159,D166,D171,D177,D196,D202) -> 87249.429 | E31: =SUM(E32,E46,E124,E132,E137,E149,E159,E166,E171,E177,E196,E202) -> 86749.429 | F31: =SUM(F32,F46,F124,F132,F137,F149,F159,F166,F171,F177,F196,F202) -> 93849.429 | G31: =SUM(G32,G46,G124,G132,G137,G149,G159,G166,G171,G177,G196,G202) -> 97110.349 | H31: =SUM(H32,H46,H124,H132,H137,H149,H159,H166,H171,H177,H196,H202) -> 71976.44 | I31: =SUM(I32,I46,I124,I132,I137,I149,I159,I166,I171,I177,I196,I202) -> 72476.44 | J31: =SUM(J32,J46,J124,J132,J137,J149,J159,J166,J171,J177,J196,J202) -> 47076.44 | ... N31: =SUM(N32,N46,N124,N132,N137,N149,N159,N166,N171,N177,N196,N202) -> 50976.44 | O31: =SUM(C31:N31) -> 812913.14
B32: PESSOAL (CLT e PJ recorrente) | C32: =SUM(C33:C45) -> 26560 | D32: =SUM(D33:D45) -> 26560 | E32: =SUM(E33:E45) -> 26560 | F32: =SUM(F33:F45) -> 26560 | G32: =SUM(G33:G45) -> 26560 | H32: =SUM(H33:H45) -> 26560 | I32: =SUM(I33:I45) -> 26560 | J32: =SUM(J33:J45) -> 26560 | ... N32: =SUM(N33:N45) -> 26560 | O32: =SUM(C32:N32) -> 318720 | Q32: Emnanuel | R32: Faturamento
B33: CEO - Denis Julio | C33: 13000 | D33: 13000 | E33: 13000 | F33: 13000 | G33: 13000 | H33: 13000 | I33: 13000 | J33: 13000 | K33: 13000 | L33: 13000 | M33: 13000 | N33: 13000 | O33: =SUM(C33:N33) -> 156000 | Q33: Escola | R33: 2800
B34: Gerente Administrativo - Renato Assis | C34: 6000 | D34: 6000 | E34: 6000 | F34: 6000 | G34: 6000 | H34: 6000 | I34: 6000 | J34: 6000 | K34: 6000 | L34: 6000 | M34: 6000 | N34: 6000 | O34: =SUM(C34:N34) -> 72000 | Q34: Faculdade | R34: 2500
B35: Analista de Marketing - Emanuel Peixoto | C35: 3000 | D35: 3000 | E35: 3000 | F35: 3000 | G35: 3000 | H35: 3000 | I35: 3000 | J35: 3000 | K35: 3000 | L35: 3000 | M35: 3000 | N35: 3000 | O35: =SUM(C35:N35) -> 36000 | Q35: Education | R35: 3300
B36: Consultor pedagógico 1 - Suzana | C36: 2000 | D36: 2000 | E36: 2000 | F36: 2000 | G36: 2000 | H36: 2000 | I36: 2000 | J36: 2000 | K36: 2000 | L36: 2000 | M36: 2000 | N36: 2000 | O36: =SUM(C36:N36) -> 24000 | Q36: Dr. Marcos | R36: 2500
B37: Consultor pedagógico 2 | O37: =SUM(C37:N37) -> 0 | Q37: Centro Paraibano | R37: 1800
B38: Representante Comercial - Christiano Bonifazio | C38: 2000 | D38: 2000 | E38: 2000 | F38: 2000 | G38: 2000 | H38: 2000 | I38: 2000 | J38: 2000 | K38: 2000 | L38: 2000 | M38: 2000 | N38: 2000 | O38: =SUM(C38:N38) -> 24000 | Q38: We Make | R38: 2000
B39: Contador | C39: 400 | D39: 400 | E39: 400 | F39: 400 | G39: 400 | H39: 400 | I39: 400 | J39: 400 | K39: 400 | L39: 400 | M39: 400 | N39: 400 | O39: =SUM(C39:N39) -> 4800 | Q39: Pet Shop | R39: 1000
B40: Atendente comercial | O40: =SUM(C40:N40) -> 0
B41: Treinamento de pessoal
B42: Pós-graduação em Educação Cristã Clássica para Suzana Bonifazio | C42: 80 | D42: 80 | E42: 80 | F42: 80 | G42: 80 | H42: 80 | I42: 80 | J42: 80 | K42: 80 | L42: 80 | M42: 80 | N42: 80 | O42: =SUM(C42:N42) -> 960
B43: Pós-graduação em Educação Cristã Clássica para Christiano Bonifazio | C43: 80 | D43: 80 | E43: 80 | F43: 80 | G43: 80 | H43: 80 | I43: 80 | J43: 80 | K43: 80 | L43: 80 | M43: 80 | N43: 80 | O43: =SUM(C43:N43) -> 960
...

Sheet Alunos_escola_livros
A1: Escola | B1: Quantidade de alunos
B2: Infantil IV | C2: Infantil V | D2: 1º ano Ensino Fundamental I | E2: 2º ano Ensino Fundamental I | F2: 3º ano Ensino Fundamental I | G2: 4º ano Ensino Fundamental I | H2: 5º ano Ensino Fundamental I | I2: 6º ano Ensino Fundamental II | J2: 7º ano Ensino Fundamental II | K2: 8º ano Ensino Fundamental II | L2: 9º ano Ensino Fundamental II | M2: 1ª série Ensino Médio - Programação e Jogos (Ensino Médio) | N2: 2ª série Ensino Médio - Modelagem e Impressão 3D (Ensino Médio) | O2: 3ª série Ensino Médio - Robótica e Automação (Ensino Médio) | P2: Total
A3: Colégio Graciosa (ano 1/4) | B3: 0 | C3: 0 | D3: 28 | E3: 34 | F3: 41 | G3: 32 | H3: 38 | I3: 45 | J3: 39 | K3: 33 | L3: 19 | M3: 0 | N3: 0 | O3: 0 | P3: =SUM(B3:O3) -> 309
A4: Colégio Cristão Amar (ano 3/4) | B4: 0 | C4: 0 | D4: 0 | E4: 0 | F4: 0 | G4: 0 | H4: 0 | I4: 234 | P4: =SUM(B4:O4) -> 234
A5: Colégio Journey (ano 3/5) | B5: 0 | C5: 0 | D5: 0 | E5: 0 | F5: 0 | G5: 0 | H5: 8 | I5: 32 | J5: 46 | K5: 38 | L5: 37 | M5: 68 | N5: 78 | O5: 41 | P5: =SUM(B5:O5) -> 348
A6: Executivo Colégio e Curso (gratuito) | B6: 0 | C6: 0 | D6: 0 | E6: 0 | F6: 0 | G6: 0 | H6: 0 | I6: 0 | J6: 0 | K6: 0 | L6: 0 | M6: 0 | N6: 0 | O6: 0 | P6: =SUM(B6:O6) -> 0
A7: Escola Cristã do Reino (2/4) | B7: 0 | C7: 0 | D7: 12 | E7: 7 | F7: 0 | G7: 0 | H7: 0 | I7: 0 | J7: 0 | K7: 0 | L7: 0 | M7: 0 | N7: 0 | O7: 0 | P7: =SUM(B7:O7) -> 19
A8: Escola Aprender e Viver (2/4) | B8: 0 | C8: 0 | D8: 130 | M8: 0 | N8: 0 | O8: 0 | P8: =SUM(B8:O8) -> 130
A9: Educar Londrina (2/4) | B9: 0 | C9: 0 | D9: 23 | E9: 31 | F9: 21 | G9: 21 | H9: 42 | I9: 58 | J9: 34 | K9: 29 | L9: 16 | M9: 19 | N9: 11 | O9: 17 | P9: =SUM(B9:O9) -> 322
A10: CESE (2/4) | B10: 0 | C10: 0 | D10: 210 | M10: 0 | N10: 0 | O10: 0 | P10: =SUM(B10:O10) -> 210
A11: CEA (2/4) | B11: 0 | C11: 0 | D11: 6 | E11: 3 | F11: 5 | G11: 2 | H11: 0 | I11: 4 | J11: 0 | K11: 0 | L11: 0 | M11: 0 | N11: 0 | O11: 0 | P11: =SUM(B11:O11) -> 20
A12: Sagrados corações (2/4) | B12: 0 | C12: 0 | D12: 60 | J12: 0 | K12: 0 | L12: 0 | M12: 0 | N12: 0 | O12: 0 | P12: =SUM(B12:O12) -> 60
A13: ACR Classical Christian School (2/4) | B13: 0 | C13: 0 | D13: 42 | I13: 0 | J13: 0 | K13: 0 | L13: 0 | M13: 0 | N13: 0 | O13: 0 | P13: =SUM(B13:O13) -> 42
A14: Escola Cristã Paz (1/4) | B14: 0 | C14: 0 | D14: 180 | M14: 0 | N14: 0 | O14: 0 | P14: =SUM(B14:O14) -> 180
A15: Colégio da Comunidade - Curuçá (1/4) | B15: 0 | C15: 0 | D15: 27 | E15: 35 | F15: 34 | G15: 33 | H15: 35 | I15: 39 | J15: 25 | K15: 25 | L15: 19 | M15: 0 | N15: 0 | O15: 0 | P15: =SUM(B15:O15) -> 272
A16: Colégio da Comunidade - Carrão (1/4) | B16: 0 | C16: 0 | D16: 22 | E16: 29 | F16: 28 | G16: 34 | H16: 43 | I16: 42 | J16: 45 | K16: 49 | L16: 39 | M16: 0 | N16: 0 | O16: 0 | P16: =SUM(B16:O16) -> 331
A17: Escola Estímulos (1/4) | B17: 0 | C17: 0 | D17: 0 | E17: 0 | F17: 0 | G17: 0 | H17: 0 | I17: 0 | J17: 0 | K17: 0 | L17: 0 | M17: 0 | N17: 0 | O17: 0 | P17: =SUM(B17:O17) -> 0
A18: Colégio Cristão Reverendo Olavo Nunes (1/4) | B18: 0 | C18: 0 | D18: 90 | I18: 0 | J18: 0 | K18: 0 | L18: 0 | M18: 0 | N18: 0 | O18: 0 | P18: =SUM(B18:O18) -> 90
A19: Colégio Cristão Zoe (1/4) | B19: 10 | C19: 10 | D19: 14 | E19: 12 | F19: 12 | G19: 10 | H19: 10 | I19: 0 | J19: 0 | K19: 0 | L19: 0 | M19: 0 | N19: 0 | O19: 0 | P19: =SUM(B19:O19) -> 78
A20: Colégio Lighthouse F1 (1/4) | B20: 0 | C20: 0 | D20: 0 | E20: 0 | F20: 0 | G20: 25 | H20: 32 | I20: 0 | J20: 0 | K20: 0 | L20: 0 | M20: 0 | N20: 0 | O20: 0 | P20: =SUM(B20:O20) -> 57
A21: Colégio Lighthouse F2 (1/4) | B21: 0 | C21: 0 | D21: 0 | E21: 0 | F21: 0 | G21: 0 | H21: 0 | I21: 25 | J21: 34 | K21: 0 | L21: 0 | M21: 0 | N21: 0 | O21: 0 | P21: =SUM(B21:O21) -> 59
A22: Bee Christian School (1/5) | B22: 230 | P22: =SUM(B22:O22) -> 230
A23: For Life (1/4) | B23: 0 | C23: 0 | D23: 15 | E23: 15 | F23: 15 | G23: 15 | H23: 15 | I23: 15 | J23: 15 | K23: 15 | L23: 15 | M23: 0 | N23: 0 | O23: 0 | P23: =SUM(B23:O23) -> 135
A24: Escola Supremo | B24: 0 | C24: 0 | D24: 114 | I24: 0 | J24: 0 | K24: 0 | L24: 0 | M24: 0 | N24: 0 | O24: 0 | P24: =SUM(B24:O24) -> 114
A25: Total | P25: =SUM(P3:P24) -> 3240
